[2024-07-24T07:02:12.844+0000] {local_task_job_runner.py:120} INFO - ::group::Pre task execution logs
[2024-07-24T07:02:12.862+0000] {taskinstance.py:2076} INFO - Dependencies all met for dep_context=non-requeueable deps ti=<TaskInstance: s3_to_google_places_local.process_locations manual__2024-07-24T07:02:11.630737+00:00 [queued]>
[2024-07-24T07:02:12.867+0000] {taskinstance.py:2076} INFO - Dependencies all met for dep_context=requeueable deps ti=<TaskInstance: s3_to_google_places_local.process_locations manual__2024-07-24T07:02:11.630737+00:00 [queued]>
[2024-07-24T07:02:12.868+0000] {taskinstance.py:2306} INFO - Starting attempt 1 of 2
[2024-07-24T07:02:12.876+0000] {taskinstance.py:2330} INFO - Executing <Task(PythonOperator): process_locations> on 2024-07-24 07:02:11.630737+00:00
[2024-07-24T07:02:12.880+0000] {warnings.py:112} WARNING - /home/***/.local/lib/python3.12/site-packages/***/task/task_runner/standard_task_runner.py:62: DeprecationWarning: This process (pid=1940) is multi-threaded, use of fork() may lead to deadlocks in the child.
  pid = os.fork()

[2024-07-24T07:02:12.880+0000] {standard_task_runner.py:64} INFO - Started process 1942 to run task
[2024-07-24T07:02:12.881+0000] {standard_task_runner.py:90} INFO - Running: ['***', 'tasks', 'run', 's3_to_google_places_local', 'process_locations', 'manual__2024-07-24T07:02:11.630737+00:00', '--job-id', '85', '--raw', '--subdir', 'DAGS_FOLDER/accommodations.py', '--cfg-path', '/tmp/tmp9yyaspn2']
[2024-07-24T07:02:12.883+0000] {standard_task_runner.py:91} INFO - Job 85: Subtask process_locations
[2024-07-24T07:02:12.939+0000] {task_command.py:426} INFO - Running <TaskInstance: s3_to_google_places_local.process_locations manual__2024-07-24T07:02:11.630737+00:00 [running]> on host 7f96a5b4d944
[2024-07-24T07:02:13.019+0000] {taskinstance.py:2648} INFO - Exporting env vars: AIRFLOW_CTX_DAG_EMAIL='your.email@example.com' AIRFLOW_CTX_DAG_OWNER='***' AIRFLOW_CTX_DAG_ID='s3_to_google_places_local' AIRFLOW_CTX_TASK_ID='process_locations' AIRFLOW_CTX_EXECUTION_DATE='2024-07-24T07:02:11.630737+00:00' AIRFLOW_CTX_TRY_NUMBER='1' AIRFLOW_CTX_DAG_RUN_ID='manual__2024-07-24T07:02:11.630737+00:00'
[2024-07-24T07:02:13.020+0000] {taskinstance.py:430} INFO - ::endgroup::
[2024-07-24T07:02:13.050+0000] {base.py:84} INFO - Using connection ID 'aws_default' for task execution.
[2024-07-24T07:02:13.051+0000] {connection_wrapper.py:388} INFO - AWS Connection (conn_id='aws_default', conn_type='aws') credentials retrieved from login and password.
[2024-07-24T07:02:14.727+0000] {taskinstance.py:441} INFO - ::group::Post task execution logs
[2024-07-24T07:02:14.727+0000] {taskinstance.py:2905} ERROR - Task failed with exception
Traceback (most recent call last):
  File "/home/airflow/.local/lib/python3.12/site-packages/airflow/models/taskinstance.py", line 465, in _execute_task
    result = _execute_callable(context=context, **execute_callable_kwargs)
             ^^^^^^^^^^^^^^^^^^^^^^^^^^^^^^^^^^^^^^^^^^^^^^^^^^^^^^^^^^^^^
  File "/home/airflow/.local/lib/python3.12/site-packages/airflow/models/taskinstance.py", line 432, in _execute_callable
    return execute_callable(context=context, **execute_callable_kwargs)
           ^^^^^^^^^^^^^^^^^^^^^^^^^^^^^^^^^^^^^^^^^^^^^^^^^^^^^^^^^^^^
  File "/home/airflow/.local/lib/python3.12/site-packages/airflow/models/baseoperator.py", line 401, in wrapper
    return func(self, *args, **kwargs)
           ^^^^^^^^^^^^^^^^^^^^^^^^^^^
  File "/home/airflow/.local/lib/python3.12/site-packages/airflow/operators/python.py", line 235, in execute
    return_value = self.execute_callable()
                   ^^^^^^^^^^^^^^^^^^^^^^^
  File "/home/airflow/.local/lib/python3.12/site-packages/airflow/operators/python.py", line 252, in execute_callable
    return self.python_callable(*self.op_args, **self.op_kwargs)
           ^^^^^^^^^^^^^^^^^^^^^^^^^^^^^^^^^^^^^^^^^^^^^^^^^^^^^
  File "/opt/airflow/dags/accommodations.py", line 54, in process_locations
    result_df.to_csv('/path/to/your/local/AE_Accommodations_2024-07-24.csv', index=False)
  File "/home/airflow/.local/lib/python3.12/site-packages/pandas/core/generic.py", line 3902, in to_csv
    return DataFrameRenderer(formatter).to_csv(
           ^^^^^^^^^^^^^^^^^^^^^^^^^^^^^^^^^^^^
  File "/home/airflow/.local/lib/python3.12/site-packages/pandas/io/formats/format.py", line 1152, in to_csv
    csv_formatter.save()
  File "/home/airflow/.local/lib/python3.12/site-packages/pandas/io/formats/csvs.py", line 247, in save
    with get_handle(
         ^^^^^^^^^^^
  File "/home/airflow/.local/lib/python3.12/site-packages/pandas/io/common.py", line 739, in get_handle
    check_parent_directory(str(handle))
  File "/home/airflow/.local/lib/python3.12/site-packages/pandas/io/common.py", line 604, in check_parent_directory
    raise OSError(rf"Cannot save file into a non-existent directory: '{parent}'")
OSError: Cannot save file into a non-existent directory: '/path/to/your/local'
[2024-07-24T07:02:14.740+0000] {taskinstance.py:1206} INFO - Marking task as UP_FOR_RETRY. dag_id=s3_to_google_places_local, task_id=process_locations, run_id=manual__2024-07-24T07:02:11.630737+00:00, execution_date=20240724T070211, start_date=20240724T070212, end_date=20240724T070214
[2024-07-24T07:02:14.751+0000] {standard_task_runner.py:110} ERROR - Failed to execute job 85 for task process_locations (Cannot save file into a non-existent directory: '/path/to/your/local'; 1942)
[2024-07-24T07:02:14.778+0000] {local_task_job_runner.py:243} INFO - Task exited with return code 1
[2024-07-24T07:02:14.796+0000] {taskinstance.py:3503} INFO - 0 downstream tasks scheduled from follow-on schedule check
[2024-07-24T07:02:14.797+0000] {local_task_job_runner.py:222} INFO - ::endgroup::
