[2024-07-24T05:07:04.969+0000] {local_task_job_runner.py:120} INFO - ::group::Pre task execution logs
[2024-07-24T05:07:04.981+0000] {taskinstance.py:2076} INFO - Dependencies all met for dep_context=non-requeueable deps ti=<TaskInstance: s3_file_import_dag.get_s3_data manual__2024-07-24T05:07:04.027234+00:00 [queued]>
[2024-07-24T05:07:04.984+0000] {taskinstance.py:2076} INFO - Dependencies all met for dep_context=requeueable deps ti=<TaskInstance: s3_file_import_dag.get_s3_data manual__2024-07-24T05:07:04.027234+00:00 [queued]>
[2024-07-24T05:07:04.984+0000] {taskinstance.py:2306} INFO - Starting attempt 1 of 2
[2024-07-24T05:07:04.989+0000] {taskinstance.py:2330} INFO - Executing <Task(PythonOperator): get_s3_data> on 2024-07-24 05:07:04.027234+00:00
[2024-07-24T05:07:04.995+0000] {warnings.py:112} WARNING - /home/***/.local/lib/python3.12/site-packages/***/task/task_runner/standard_task_runner.py:62: DeprecationWarning: This process (pid=250) is multi-threaded, use of fork() may lead to deadlocks in the child.
  pid = os.fork()

[2024-07-24T05:07:04.996+0000] {standard_task_runner.py:64} INFO - Started process 251 to run task
[2024-07-24T05:07:04.996+0000] {standard_task_runner.py:90} INFO - Running: ['***', 'tasks', 'run', 's3_file_import_dag', 'get_s3_data', 'manual__2024-07-24T05:07:04.027234+00:00', '--job-id', '13', '--raw', '--subdir', 'DAGS_FOLDER/accommodations.py', '--cfg-path', '/tmp/tmp0kmt1k_0']
[2024-07-24T05:07:04.997+0000] {standard_task_runner.py:91} INFO - Job 13: Subtask get_s3_data
[2024-07-24T05:07:05.044+0000] {task_command.py:426} INFO - Running <TaskInstance: s3_file_import_dag.get_s3_data manual__2024-07-24T05:07:04.027234+00:00 [running]> on host 7f96a5b4d944
[2024-07-24T05:07:05.126+0000] {taskinstance.py:2648} INFO - Exporting env vars: AIRFLOW_CTX_DAG_EMAIL='your.email@example.com' AIRFLOW_CTX_DAG_OWNER='***' AIRFLOW_CTX_DAG_ID='s3_file_import_dag' AIRFLOW_CTX_TASK_ID='get_s3_data' AIRFLOW_CTX_EXECUTION_DATE='2024-07-24T05:07:04.027234+00:00' AIRFLOW_CTX_TRY_NUMBER='1' AIRFLOW_CTX_DAG_RUN_ID='manual__2024-07-24T05:07:04.027234+00:00'
[2024-07-24T05:07:05.127+0000] {taskinstance.py:430} INFO - ::endgroup::
[2024-07-24T05:07:05.153+0000] {base.py:84} INFO - Using connection ID 'aws_default' for task execution.
[2024-07-24T05:07:05.153+0000] {connection_wrapper.py:388} INFO - AWS Connection (conn_id='aws_default', conn_type='aws') credentials retrieved from login and password.
[2024-07-24T05:07:05.344+0000] {taskinstance.py:441} INFO - ::group::Post task execution logs
[2024-07-24T05:07:05.345+0000] {taskinstance.py:2905} ERROR - Task failed with exception
Traceback (most recent call last):
  File "/home/airflow/.local/lib/python3.12/site-packages/airflow/models/taskinstance.py", line 465, in _execute_task
    result = _execute_callable(context=context, **execute_callable_kwargs)
             ^^^^^^^^^^^^^^^^^^^^^^^^^^^^^^^^^^^^^^^^^^^^^^^^^^^^^^^^^^^^^
  File "/home/airflow/.local/lib/python3.12/site-packages/airflow/models/taskinstance.py", line 432, in _execute_callable
    return execute_callable(context=context, **execute_callable_kwargs)
           ^^^^^^^^^^^^^^^^^^^^^^^^^^^^^^^^^^^^^^^^^^^^^^^^^^^^^^^^^^^^
  File "/home/airflow/.local/lib/python3.12/site-packages/airflow/models/baseoperator.py", line 401, in wrapper
    return func(self, *args, **kwargs)
           ^^^^^^^^^^^^^^^^^^^^^^^^^^^
  File "/home/airflow/.local/lib/python3.12/site-packages/airflow/operators/python.py", line 235, in execute
    return_value = self.execute_callable()
                   ^^^^^^^^^^^^^^^^^^^^^^^
  File "/home/airflow/.local/lib/python3.12/site-packages/airflow/operators/python.py", line 252, in execute_callable
    return self.python_callable(*self.op_args, **self.op_kwargs)
           ^^^^^^^^^^^^^^^^^^^^^^^^^^^^^^^^^^^^^^^^^^^^^^^^^^^^^
  File "/opt/airflow/dags/accommodations.py", line 13, in get_s3_data
    content = hook.read_key(key, bucket_name)
              ^^^^^^^^^^^^^^^^^^^^^^^^^^^^^^^
  File "/home/airflow/.local/lib/python3.12/site-packages/airflow/providers/amazon/aws/hooks/s3.py", line 156, in wrapper
    return func(*bound_args.args, **bound_args.kwargs)
           ^^^^^^^^^^^^^^^^^^^^^^^^^^^^^^^^^^^^^^^^^^^
  File "/home/airflow/.local/lib/python3.12/site-packages/airflow/providers/amazon/aws/hooks/s3.py", line 130, in wrapper
    return func(*bound_args.args, **bound_args.kwargs)
           ^^^^^^^^^^^^^^^^^^^^^^^^^^^^^^^^^^^^^^^^^^^
  File "/home/airflow/.local/lib/python3.12/site-packages/airflow/providers/amazon/aws/hooks/s3.py", line 979, in read_key
    obj = self.get_key(key, bucket_name)
          ^^^^^^^^^^^^^^^^^^^^^^^^^^^^^^
  File "/home/airflow/.local/lib/python3.12/site-packages/airflow/providers/amazon/aws/hooks/s3.py", line 156, in wrapper
    return func(*bound_args.args, **bound_args.kwargs)
           ^^^^^^^^^^^^^^^^^^^^^^^^^^^^^^^^^^^^^^^^^^^
  File "/home/airflow/.local/lib/python3.12/site-packages/airflow/providers/amazon/aws/hooks/s3.py", line 130, in wrapper
    return func(*bound_args.args, **bound_args.kwargs)
           ^^^^^^^^^^^^^^^^^^^^^^^^^^^^^^^^^^^^^^^^^^^
  File "/home/airflow/.local/lib/python3.12/site-packages/airflow/providers/amazon/aws/hooks/s3.py", line 963, in get_key
    obj.load(**sanitize_extra_args())
  File "/home/airflow/.local/lib/python3.12/site-packages/boto3/resources/factory.py", line 565, in do_action
    response = action(self, *args, **kwargs)
               ^^^^^^^^^^^^^^^^^^^^^^^^^^^^^
  File "/home/airflow/.local/lib/python3.12/site-packages/boto3/resources/action.py", line 88, in __call__
    response = getattr(parent.meta.client, operation_name)(*args, **params)
               ^^^^^^^^^^^^^^^^^^^^^^^^^^^^^^^^^^^^^^^^^^^^^^^^^^^^^^^^^^^^
  File "/home/airflow/.local/lib/python3.12/site-packages/botocore/client.py", line 565, in _api_call
    return self._make_api_call(operation_name, kwargs)
           ^^^^^^^^^^^^^^^^^^^^^^^^^^^^^^^^^^^^^^^^^^^
  File "/home/airflow/.local/lib/python3.12/site-packages/botocore/client.py", line 1021, in _make_api_call
    raise error_class(parsed_response, operation_name)
botocore.exceptions.ClientError: An error occurred (404) when calling the HeadObject operation: Not Found
[2024-07-24T05:07:05.363+0000] {taskinstance.py:1206} INFO - Marking task as UP_FOR_RETRY. dag_id=s3_file_import_dag, task_id=get_s3_data, run_id=manual__2024-07-24T05:07:04.027234+00:00, execution_date=20240724T050704, start_date=20240724T050704, end_date=20240724T050705
[2024-07-24T05:07:05.382+0000] {standard_task_runner.py:110} ERROR - Failed to execute job 13 for task get_s3_data (An error occurred (404) when calling the HeadObject operation: Not Found; 251)
[2024-07-24T05:07:05.410+0000] {local_task_job_runner.py:243} INFO - Task exited with return code 1
[2024-07-24T05:07:05.438+0000] {taskinstance.py:3503} INFO - 0 downstream tasks scheduled from follow-on schedule check
[2024-07-24T05:07:05.440+0000] {local_task_job_runner.py:222} INFO - ::endgroup::
